<?xml version='1.0'?>
<sdf version='1.7'>
  <model name='SpotRobot_1'>
    <link name='body'>
      <inertial>
        <mass>1</mass>
        <inertia>
          <ixx>0.166667</ixx>
          <ixy>0</ixy>
          <ixz>0</ixz>
          <iyy>0.166667</iyy>
          <iyz>0</iyz>
          <izz>0.166667</izz>
        </inertia>
        <pose>0 0 0 0 -0 0</pose>
      </inertial>
      <pose>0 0 0.85 -9.6e-05 -1.5707 9.6e-05</pose>
      <gravity>1</gravity>
      <self_collide>0</self_collide>
      <kinematic>0</kinematic>
      <enable_wind>0</enable_wind>
      <visual name='visual'>
        <pose>0 0 -0.215 0 -0 0</pose>
        <geometry>
          <polyline>
            <height>0.435</height>
            <point>0.112804 -0.768739</point>
            <point>0.182436 -0.526419</point>
            <point>0.182436 0.674039</point>
            <point>0.115589 0.768739</point>
            <point>-0.182436 0.710248</point>
            <point>-0.129516 -0.598837</point>
            <point>-0.154583 -0.67961</point>
            <point>0.112804 -0.768739</point>
          </polyline>
        </geometry>
        <material>
          <lighting>1</lighting>
          <script>
            <uri>file://media/materials/scripts/gazebo.material</uri>
            <name>Gazebo/DarkYellow</name>
          </script>
          <shader type='pixel'/>
          <emissive>0 0 0 1</emissive>
        </material>
        <transparency>0</transparency>
        <cast_shadows>1</cast_shadows>
      </visual>
      <collision name='collision'>
        <laser_retro>0</laser_retro>
        <max_contacts>10</max_contacts>
        <pose>0 0 -0.215 0 -0 0</pose>
        <geometry>
          <polyline>
            <height>0.435</height>
            <point>0.112804 -0.768739</point>
            <point>0.182436 -0.526419</point>
            <point>0.182436 0.674039</point>
            <point>0.115589 0.768739</point>
            <point>-0.182436 0.710248</point>
            <point>-0.129516 -0.598837</point>
            <point>-0.154583 -0.67961</point>
            <point>0.112804 -0.768739</point>
          </polyline>
        </geometry>
        <surface>
          <friction>
            <ode>
              <mu>1</mu>
              <mu2>1</mu2>
              <fdir1>0 0 0</fdir1>
              <slip1>0</slip1>
              <slip2>0</slip2>
            </ode>
            <torsional>
              <coefficient>1</coefficient>
              <patch_radius>0</patch_radius>
              <surface_radius>0</surface_radius>
              <use_patch_radius>1</use_patch_radius>
              <ode>
                <slip>0</slip>
              </ode>
            </torsional>
          </friction>
          <bounce>
            <restitution_coefficient>0</restitution_coefficient>
            <threshold>1e+06</threshold>
          </bounce>
          <contact>
            <collide_without_contact>0</collide_without_contact>
            <collide_without_contact_bitmask>1</collide_without_contact_bitmask>
            <collide_bitmask>1</collide_bitmask>
            <ode>
              <soft_cfm>0</soft_cfm>
              <soft_erp>0.2</soft_erp>
              <kp>1e+13</kp>
              <kd>1</kd>
              <max_vel>0.01</max_vel>
              <min_depth>0</min_depth>
            </ode>
            <bullet>
              <split_impulse>1</split_impulse>
              <split_impulse_penetration_threshold>-0.01</split_impulse_penetration_threshold>
              <soft_cfm>0</soft_cfm>
              <soft_erp>0.2</soft_erp>
              <kp>1e+13</kp>
              <kd>1</kd>
            </bullet>
          </contact>
        </surface>
      </collision>
    </link>
    <link name='bottomleg_frontleft'>
      <inertial>
        <mass>1</mass>
        <inertia>
          <ixx>0.166667</ixx>
          <ixy>0</ixy>
          <ixz>0</ixz>
          <iyy>0.166667</iyy>
          <iyz>0</iyz>
          <izz>0.166667</izz>
        </inertia>
        <pose>0 0 0 0 -0 0</pose>
      </inertial>
      <pose>0.472209 -0.084066 0.9 -1.55166 -1.55076 1.55997</pose>
      <gravity>1</gravity>
      <self_collide>0</self_collide>
      <kinematic>0</kinematic>
      <enable_wind>0</enable_wind>
      <visual name='visual'>
        <pose>-0.14 -0.28 -0.05 0 -0 0</pose>
        <geometry>
          <polyline>
            <height>0.1</height>
            <point>-0.000605438 -0.193129</point>
            <point>-0.0321982 -0.143407</point>
            <point>-0.126743 -0.168287</point>
            <point>-0.138907 -0.178459</point>
            <point>-0.147472 -0.191021</point>
            <point>-0.152612 -0.204726</point>
            <point>-0.152612 -0.220715</point>
            <point>-0.150746 -0.235978</point>
            <point>-0.144588 -0.249577</point>
            <point>-0.134325 -0.262149</point>
            <point>-0.121496 -0.27036</point>
            <point>-0.10764 -0.275235</point>
            <point>-0.0926418 -0.277035</point>
            <point>-0.0769904 -0.274213</point>
            <point>-0.0615955 -0.267799</point>
            <point>-0.000605438 -0.193129</point>
          </polyline>
          <polyline>
            <height>0.1</height>
            <point>-0.0401085 -0.133327</point>
            <point>-0.138961 -0.147488</point>
            <point>-0.155521 -0.164048</point>
            <point>-0.168654 -0.180037</point>
            <point>-0.176078 -0.200023</point>
            <point>-0.17722 -0.223436</point>
            <point>-0.173481 -0.243336</point>
            <point>-0.163529 -0.263623</point>
            <point>-0.149366 -0.279699</point>
            <point>-0.131759 -0.291565</point>
            <point>-0.113003 -0.299221</point>
            <point>-0.0908969 -0.301066</point>
            <point>-0.0690875 -0.29696</point>
            <point>-0.0493307 -0.287724</point>
            <point>0.0107182 -0.197705</point>
            <point>0.0601272 -0.111665</point>
            <point>0.105738 -0.0191367</point>
            <point>0.145777 0.0984226</point>
            <point>0.166222 0.187018</point>
            <point>0.17722 0.267953</point>
            <point>0.174158 0.277777</point>
            <point>0.16765 0.288112</point>
            <point>0.162436 0.293842</point>
            <point>0.154524 0.298314</point>
            <point>0.145409 0.301066</point>
            <point>0.134401 0.301066</point>
            <point>0.12477 0.298314</point>
            <point>0.116799 0.293669</point>
            <point>0.109919 0.286617</point>
            <point>0.105275 0.27819</point>
            <point>0.102867 0.267953</point>
            <point>0.105265 0.232247</point>
            <point>0.105265 0.196583</point>
            <point>0.102183 0.158496</point>
            <point>0.0964418 0.11907</point>
            <point>0.0864897 0.0788786</point>
            <point>0.0684993 0.0283524</point>
            <point>0.0401947 -0.0290691</point>
            <point>-0.000707322 -0.092784</point>
            <point>-0.0401085 -0.133327</point>
          </polyline>
        </geometry>
        <material>
          <lighting>1</lighting>
          <script>
            <uri>file://media/materials/scripts/gazebo.material</uri>
            <name>Gazebo/FlatBlack</name>
          </script>
          <shader type='pixel'>
            <normal_map>__default__</normal_map>
          </shader>
          <emissive>0 0 0 1</emissive>
          <ambient>0.1 0.1 0.1 1</ambient>
          <diffuse>0.1 0.1 0.1 1</diffuse>
          <specular>0.01 0.01 0.01 1</specular>
        </material>
        <transparency>0</transparency>
        <cast_shadows>1</cast_shadows>
      </visual>
      <collision name='collision'>
        <laser_retro>0</laser_retro>
        <max_contacts>10</max_contacts>
        <pose>-0.14 -0.28 -0.05 0 -0 0</pose>
        <geometry>
          <polyline>
            <height>0.1</height>
            <point>-0.000605438 -0.193129</point>
            <point>-0.0321982 -0.143407</point>
            <point>-0.126743 -0.168287</point>
            <point>-0.138907 -0.178459</point>
            <point>-0.147472 -0.191021</point>
            <point>-0.152612 -0.204726</point>
            <point>-0.152612 -0.220715</point>
            <point>-0.150746 -0.235978</point>
            <point>-0.144588 -0.249577</point>
            <point>-0.134325 -0.262149</point>
            <point>-0.121496 -0.27036</point>
            <point>-0.10764 -0.275235</point>
            <point>-0.0926418 -0.277035</point>
            <point>-0.0769904 -0.274213</point>
            <point>-0.0615955 -0.267799</point>
            <point>-0.000605438 -0.193129</point>
          </polyline>
          <polyline>
            <height>0.1</height>
            <point>-0.0401085 -0.133327</point>
            <point>-0.138961 -0.147488</point>
            <point>-0.155521 -0.164048</point>
            <point>-0.168654 -0.180037</point>
            <point>-0.176078 -0.200023</point>
            <point>-0.17722 -0.223436</point>
            <point>-0.173481 -0.243336</point>
            <point>-0.163529 -0.263623</point>
            <point>-0.149366 -0.279699</point>
            <point>-0.131759 -0.291565</point>
            <point>-0.113003 -0.299221</point>
            <point>-0.0908969 -0.301066</point>
            <point>-0.0690875 -0.29696</point>
            <point>-0.0493307 -0.287724</point>
            <point>0.0107182 -0.197705</point>
            <point>0.0601272 -0.111665</point>
            <point>0.105738 -0.0191367</point>
            <point>0.145777 0.0984226</point>
            <point>0.166222 0.187018</point>
            <point>0.17722 0.267953</point>
            <point>0.174158 0.277777</point>
            <point>0.16765 0.288112</point>
            <point>0.162436 0.293842</point>
            <point>0.154524 0.298314</point>
            <point>0.145409 0.301066</point>
            <point>0.134401 0.301066</point>
            <point>0.12477 0.298314</point>
            <point>0.116799 0.293669</point>
            <point>0.109919 0.286617</point>
            <point>0.105275 0.27819</point>
            <point>0.102867 0.267953</point>
            <point>0.105265 0.232247</point>
            <point>0.105265 0.196583</point>
            <point>0.102183 0.158496</point>
            <point>0.0964418 0.11907</point>
            <point>0.0864897 0.0788786</point>
            <point>0.0684993 0.0283524</point>
            <point>0.0401947 -0.0290691</point>
            <point>-0.000707322 -0.092784</point>
            <point>-0.0401085 -0.133327</point>
          </polyline>
        </geometry>
        <surface>
          <friction>
            <ode>
              <mu>1</mu>
              <mu2>1</mu2>
              <fdir1>0 0 0</fdir1>
              <slip1>0</slip1>
              <slip2>0</slip2>
            </ode>
            <torsional>
              <coefficient>1</coefficient>
              <patch_radius>0</patch_radius>
              <surface_radius>0</surface_radius>
              <use_patch_radius>1</use_patch_radius>
              <ode>
                <slip>0</slip>
              </ode>
            </torsional>
          </friction>
          <bounce>
            <restitution_coefficient>0</restitution_coefficient>
            <threshold>1e+06</threshold>
          </bounce>
          <contact>
            <collide_without_contact>0</collide_without_contact>
            <collide_without_contact_bitmask>1</collide_without_contact_bitmask>
            <collide_bitmask>1</collide_bitmask>
            <ode>
              <soft_cfm>0</soft_cfm>
              <soft_erp>0.2</soft_erp>
              <kp>1e+13</kp>
              <kd>1</kd>
              <max_vel>0.01</max_vel>
              <min_depth>0</min_depth>
            </ode>
            <bullet>
              <split_impulse>1</split_impulse>
              <split_impulse_penetration_threshold>-0.01</split_impulse_penetration_threshold>
              <soft_cfm>0</soft_cfm>
              <soft_erp>0.2</soft_erp>
              <kp>1e+13</kp>
              <kd>1</kd>
            </bullet>
          </contact>
        </surface>
      </collision>
    </link>
    <link name='bottomleg_frontright'>
      <inertial>
        <mass>1</mass>
        <inertia>
          <ixx>0.166667</ixx>
          <ixy>0</ixy>
          <ixz>0</ixz>
          <iyy>0.166667</iyy>
          <iyz>0</iyz>
          <izz>0.166667</izz>
        </inertia>
        <pose>0 0 0 0 -0 0</pose>
      </inertial>
      <pose>-0.391153 -0.08767 0.9 -0.000441 -1.57069 0.00044</pose>
      <gravity>1</gravity>
      <self_collide>0</self_collide>
      <kinematic>0</kinematic>
      <enable_wind>0</enable_wind>
      <visual name='visual'>
        <pose>-0.14 -0.28 -0.05 0 -0 0</pose>
        <geometry>
          <polyline>
            <height>0.1</height>
            <point>-0.000605438 -0.193129</point>
            <point>-0.0321982 -0.143407</point>
            <point>-0.126743 -0.168287</point>
            <point>-0.138907 -0.178459</point>
            <point>-0.147472 -0.191021</point>
            <point>-0.152612 -0.204726</point>
            <point>-0.152612 -0.220715</point>
            <point>-0.150746 -0.235978</point>
            <point>-0.144588 -0.249577</point>
            <point>-0.134325 -0.262149</point>
            <point>-0.121496 -0.27036</point>
            <point>-0.10764 -0.275235</point>
            <point>-0.0926418 -0.277035</point>
            <point>-0.0769904 -0.274213</point>
            <point>-0.0615955 -0.267799</point>
            <point>-0.000605438 -0.193129</point>
          </polyline>
          <polyline>
            <height>0.1</height>
            <point>-0.0401085 -0.133327</point>
            <point>-0.138961 -0.147488</point>
            <point>-0.155521 -0.164048</point>
            <point>-0.168654 -0.180037</point>
            <point>-0.176078 -0.200023</point>
            <point>-0.17722 -0.223436</point>
            <point>-0.173481 -0.243336</point>
            <point>-0.163529 -0.263623</point>
            <point>-0.149366 -0.279699</point>
            <point>-0.131759 -0.291565</point>
            <point>-0.113003 -0.299221</point>
            <point>-0.0908969 -0.301066</point>
            <point>-0.0690875 -0.29696</point>
            <point>-0.0493307 -0.287724</point>
            <point>0.0107182 -0.197705</point>
            <point>0.0601272 -0.111665</point>
            <point>0.105738 -0.0191367</point>
            <point>0.145777 0.0984226</point>
            <point>0.166222 0.187018</point>
            <point>0.17722 0.267953</point>
            <point>0.174158 0.277777</point>
            <point>0.16765 0.288112</point>
            <point>0.162436 0.293842</point>
            <point>0.154524 0.298314</point>
            <point>0.145409 0.301066</point>
            <point>0.134401 0.301066</point>
            <point>0.12477 0.298314</point>
            <point>0.116799 0.293669</point>
            <point>0.109919 0.286617</point>
            <point>0.105275 0.27819</point>
            <point>0.102867 0.267953</point>
            <point>0.105265 0.232247</point>
            <point>0.105265 0.196583</point>
            <point>0.102183 0.158496</point>
            <point>0.0964418 0.11907</point>
            <point>0.0864897 0.0788786</point>
            <point>0.0684993 0.0283524</point>
            <point>0.0401947 -0.0290691</point>
            <point>-0.000707322 -0.092784</point>
            <point>-0.0401085 -0.133327</point>
          </polyline>
        </geometry>
        <material>
          <lighting>1</lighting>
          <script>
            <uri>file://media/materials/scripts/gazebo.material</uri>
            <name>Gazebo/FlatBlack</name>
          </script>
          <shader type='pixel'>
            <normal_map>__default__</normal_map>
          </shader>
          <emissive>0 0 0 1</emissive>
          <ambient>0.1 0.1 0.1 1</ambient>
          <diffuse>0.1 0.1 0.1 1</diffuse>
          <specular>0.01 0.01 0.01 1</specular>
        </material>
        <transparency>0</transparency>
        <cast_shadows>1</cast_shadows>
      </visual>
      <collision name='collision'>
        <laser_retro>0</laser_retro>
        <max_contacts>10</max_contacts>
        <pose>-0.14 -0.28 -0.05 0 -0 0</pose>
        <geometry>
          <polyline>
            <height>0.1</height>
            <point>-0.000605438 -0.193129</point>
            <point>-0.0321982 -0.143407</point>
            <point>-0.126743 -0.168287</point>
            <point>-0.138907 -0.178459</point>
            <point>-0.147472 -0.191021</point>
            <point>-0.152612 -0.204726</point>
            <point>-0.152612 -0.220715</point>
            <point>-0.150746 -0.235978</point>
            <point>-0.144588 -0.249577</point>
            <point>-0.134325 -0.262149</point>
            <point>-0.121496 -0.27036</point>
            <point>-0.10764 -0.275235</point>
            <point>-0.0926418 -0.277035</point>
            <point>-0.0769904 -0.274213</point>
            <point>-0.0615955 -0.267799</point>
            <point>-0.000605438 -0.193129</point>
          </polyline>
          <polyline>
            <height>0.1</height>
            <point>-0.0401085 -0.133327</point>
            <point>-0.138961 -0.147488</point>
            <point>-0.155521 -0.164048</point>
            <point>-0.168654 -0.180037</point>
            <point>-0.176078 -0.200023</point>
            <point>-0.17722 -0.223436</point>
            <point>-0.173481 -0.243336</point>
            <point>-0.163529 -0.263623</point>
            <point>-0.149366 -0.279699</point>
            <point>-0.131759 -0.291565</point>
            <point>-0.113003 -0.299221</point>
            <point>-0.0908969 -0.301066</point>
            <point>-0.0690875 -0.29696</point>
            <point>-0.0493307 -0.287724</point>
            <point>0.0107182 -0.197705</point>
            <point>0.0601272 -0.111665</point>
            <point>0.105738 -0.0191367</point>
            <point>0.145777 0.0984226</point>
            <point>0.166222 0.187018</point>
            <point>0.17722 0.267953</point>
            <point>0.174158 0.277777</point>
            <point>0.16765 0.288112</point>
            <point>0.162436 0.293842</point>
            <point>0.154524 0.298314</point>
            <point>0.145409 0.301066</point>
            <point>0.134401 0.301066</point>
            <point>0.12477 0.298314</point>
            <point>0.116799 0.293669</point>
            <point>0.109919 0.286617</point>
            <point>0.105275 0.27819</point>
            <point>0.102867 0.267953</point>
            <point>0.105265 0.232247</point>
            <point>0.105265 0.196583</point>
            <point>0.102183 0.158496</point>
            <point>0.0964418 0.11907</point>
            <point>0.0864897 0.0788786</point>
            <point>0.0684993 0.0283524</point>
            <point>0.0401947 -0.0290691</point>
            <point>-0.000707322 -0.092784</point>
            <point>-0.0401085 -0.133327</point>
          </polyline>
        </geometry>
        <surface>
          <friction>
            <ode>
              <mu>1</mu>
              <mu2>1</mu2>
              <fdir1>0 0 0</fdir1>
              <slip1>0</slip1>
              <slip2>0</slip2>
            </ode>
            <torsional>
              <coefficient>1</coefficient>
              <patch_radius>0</patch_radius>
              <surface_radius>0</surface_radius>
              <use_patch_radius>1</use_patch_radius>
              <ode>
                <slip>0</slip>
              </ode>
            </torsional>
          </friction>
          <bounce>
            <restitution_coefficient>0</restitution_coefficient>
            <threshold>1e+06</threshold>
          </bounce>
          <contact>
            <collide_without_contact>0</collide_without_contact>
            <collide_without_contact_bitmask>1</collide_without_contact_bitmask>
            <collide_bitmask>1</collide_bitmask>
            <ode>
              <soft_cfm>0</soft_cfm>
              <soft_erp>0.2</soft_erp>
              <kp>1e+13</kp>
              <kd>1</kd>
              <max_vel>0.01</max_vel>
              <min_depth>0</min_depth>
            </ode>
            <bullet>
              <split_impulse>1</split_impulse>
              <split_impulse_penetration_threshold>-0.01</split_impulse_penetration_threshold>
              <soft_cfm>0</soft_cfm>
              <soft_erp>0.2</soft_erp>
              <kp>1e+13</kp>
              <kd>1</kd>
            </bullet>
          </contact>
        </surface>
      </collision>
    </link>
    <link name='bottomleg_rearleft'>
      <inertial>
        <mass>1</mass>
        <inertia>
          <ixx>0.166667</ixx>
          <ixy>0</ixy>
          <ixz>0</ixz>
          <iyy>0.166667</iyy>
          <iyz>0</iyz>
          <izz>0.166667</izz>
        </inertia>
        <pose>0 0 0 0 -0 0</pose>
      </inertial>
      <pose>0.472457 1.00094 0.9 -1.55213 -1.55076 1.56045</pose>
      <gravity>1</gravity>
      <self_collide>0</self_collide>
      <kinematic>0</kinematic>
      <enable_wind>0</enable_wind>
      <visual name='visual'>
        <pose>-0.14 -0.28 -0.05 0 -0 0</pose>
        <geometry>
          <polyline>
            <height>0.1</height>
            <point>-0.000605438 -0.193129</point>
            <point>-0.0321982 -0.143407</point>
            <point>-0.126743 -0.168287</point>
            <point>-0.138907 -0.178459</point>
            <point>-0.147472 -0.191021</point>
            <point>-0.152612 -0.204726</point>
            <point>-0.152612 -0.220715</point>
            <point>-0.150746 -0.235978</point>
            <point>-0.144588 -0.249577</point>
            <point>-0.134325 -0.262149</point>
            <point>-0.121496 -0.27036</point>
            <point>-0.10764 -0.275235</point>
            <point>-0.0926418 -0.277035</point>
            <point>-0.0769904 -0.274213</point>
            <point>-0.0615955 -0.267799</point>
            <point>-0.000605438 -0.193129</point>
          </polyline>
          <polyline>
            <height>0.1</height>
            <point>-0.0401085 -0.133327</point>
            <point>-0.138961 -0.147488</point>
            <point>-0.155521 -0.164048</point>
            <point>-0.168654 -0.180037</point>
            <point>-0.176078 -0.200023</point>
            <point>-0.17722 -0.223436</point>
            <point>-0.173481 -0.243336</point>
            <point>-0.163529 -0.263623</point>
            <point>-0.149366 -0.279699</point>
            <point>-0.131759 -0.291565</point>
            <point>-0.113003 -0.299221</point>
            <point>-0.0908969 -0.301066</point>
            <point>-0.0690875 -0.29696</point>
            <point>-0.0493307 -0.287724</point>
            <point>0.0107182 -0.197705</point>
            <point>0.0601272 -0.111665</point>
            <point>0.105738 -0.0191367</point>
            <point>0.145777 0.0984226</point>
            <point>0.166222 0.187018</point>
            <point>0.17722 0.267953</point>
            <point>0.174158 0.277777</point>
            <point>0.16765 0.288112</point>
            <point>0.162436 0.293842</point>
            <point>0.154524 0.298314</point>
            <point>0.145409 0.301066</point>
            <point>0.134401 0.301066</point>
            <point>0.12477 0.298314</point>
            <point>0.116799 0.293669</point>
            <point>0.109919 0.286617</point>
            <point>0.105275 0.27819</point>
            <point>0.102867 0.267953</point>
            <point>0.105265 0.232247</point>
            <point>0.105265 0.196583</point>
            <point>0.102183 0.158496</point>
            <point>0.0964418 0.11907</point>
            <point>0.0864897 0.0788786</point>
            <point>0.0684993 0.0283524</point>
            <point>0.0401947 -0.0290691</point>
            <point>-0.000707322 -0.092784</point>
            <point>-0.0401085 -0.133327</point>
          </polyline>
        </geometry>
        <material>
          <lighting>1</lighting>
          <script>
            <uri>file://media/materials/scripts/gazebo.material</uri>
            <name>Gazebo/FlatBlack</name>
          </script>
          <shader type='pixel'>
            <normal_map>__default__</normal_map>
          </shader>
          <emissive>0 0 0 1</emissive>
          <ambient>0.1 0.1 0.1 1</ambient>
          <diffuse>0.1 0.1 0.1 1</diffuse>
          <specular>0.01 0.01 0.01 1</specular>
        </material>
        <transparency>0</transparency>
        <cast_shadows>1</cast_shadows>
      </visual>
      <collision name='collision'>
        <laser_retro>0</laser_retro>
        <max_contacts>10</max_contacts>
        <pose>-0.14 -0.28 -0.05 0 -0 0</pose>
        <geometry>
          <polyline>
            <height>0.1</height>
            <point>-0.000605438 -0.193129</point>
            <point>-0.0321982 -0.143407</point>
            <point>-0.126743 -0.168287</point>
            <point>-0.138907 -0.178459</point>
            <point>-0.147472 -0.191021</point>
            <point>-0.152612 -0.204726</point>
            <point>-0.152612 -0.220715</point>
            <point>-0.150746 -0.235978</point>
            <point>-0.144588 -0.249577</point>
            <point>-0.134325 -0.262149</point>
            <point>-0.121496 -0.27036</point>
            <point>-0.10764 -0.275235</point>
            <point>-0.0926418 -0.277035</point>
            <point>-0.0769904 -0.274213</point>
            <point>-0.0615955 -0.267799</point>
            <point>-0.000605438 -0.193129</point>
          </polyline>
          <polyline>
            <height>0.1</height>
            <point>-0.0401085 -0.133327</point>
            <point>-0.138961 -0.147488</point>
            <point>-0.155521 -0.164048</point>
            <point>-0.168654 -0.180037</point>
            <point>-0.176078 -0.200023</point>
            <point>-0.17722 -0.223436</point>
            <point>-0.173481 -0.243336</point>
            <point>-0.163529 -0.263623</point>
            <point>-0.149366 -0.279699</point>
            <point>-0.131759 -0.291565</point>
            <point>-0.113003 -0.299221</point>
            <point>-0.0908969 -0.301066</point>
            <point>-0.0690875 -0.29696</point>
            <point>-0.0493307 -0.287724</point>
            <point>0.0107182 -0.197705</point>
            <point>0.0601272 -0.111665</point>
            <point>0.105738 -0.0191367</point>
            <point>0.145777 0.0984226</point>
            <point>0.166222 0.187018</point>
            <point>0.17722 0.267953</point>
            <point>0.174158 0.277777</point>
            <point>0.16765 0.288112</point>
            <point>0.162436 0.293842</point>
            <point>0.154524 0.298314</point>
            <point>0.145409 0.301066</point>
            <point>0.134401 0.301066</point>
            <point>0.12477 0.298314</point>
            <point>0.116799 0.293669</point>
            <point>0.109919 0.286617</point>
            <point>0.105275 0.27819</point>
            <point>0.102867 0.267953</point>
            <point>0.105265 0.232247</point>
            <point>0.105265 0.196583</point>
            <point>0.102183 0.158496</point>
            <point>0.0964418 0.11907</point>
            <point>0.0864897 0.0788786</point>
            <point>0.0684993 0.0283524</point>
            <point>0.0401947 -0.0290691</point>
            <point>-0.000707322 -0.092784</point>
            <point>-0.0401085 -0.133327</point>
          </polyline>
        </geometry>
        <surface>
          <friction>
            <ode>
              <mu>1</mu>
              <mu2>1</mu2>
              <fdir1>0 0 0</fdir1>
              <slip1>0</slip1>
              <slip2>0</slip2>
            </ode>
            <torsional>
              <coefficient>1</coefficient>
              <patch_radius>0</patch_radius>
              <surface_radius>0</surface_radius>
              <use_patch_radius>1</use_patch_radius>
              <ode>
                <slip>0</slip>
              </ode>
            </torsional>
          </friction>
          <bounce>
            <restitution_coefficient>0</restitution_coefficient>
            <threshold>1e+06</threshold>
          </bounce>
          <contact>
            <collide_without_contact>0</collide_without_contact>
            <collide_without_contact_bitmask>1</collide_without_contact_bitmask>
            <collide_bitmask>1</collide_bitmask>
            <ode>
              <soft_cfm>0</soft_cfm>
              <soft_erp>0.2</soft_erp>
              <kp>1e+13</kp>
              <kd>1</kd>
              <max_vel>0.01</max_vel>
              <min_depth>0</min_depth>
            </ode>
            <bullet>
              <split_impulse>1</split_impulse>
              <split_impulse_penetration_threshold>-0.01</split_impulse_penetration_threshold>
              <soft_cfm>0</soft_cfm>
              <soft_erp>0.2</soft_erp>
              <kp>1e+13</kp>
              <kd>1</kd>
            </bullet>
          </contact>
        </surface>
      </collision>
    </link>
    <link name='bottomleg_rearright'>
      <inertial>
        <mass>1</mass>
        <inertia>
          <ixx>0.166667</ixx>
          <ixy>0</ixy>
          <ixz>0</ixz>
          <iyy>0.166667</iyy>
          <iyz>0</iyz>
          <izz>0.166667</izz>
        </inertia>
        <pose>0 0 0 0 -0 0</pose>
      </inertial>
      <pose>-0.432007 1.00564 0.9 -1.5522 -1.55076 1.56053</pose>
      <gravity>1</gravity>
      <self_collide>0</self_collide>
      <kinematic>0</kinematic>
      <enable_wind>0</enable_wind>
      <visual name='visual'>
        <pose>-0.14 -0.28 -0.05 0 -0 0</pose>
        <geometry>
          <polyline>
            <height>0.1</height>
            <point>-0.000605438 -0.193129</point>
            <point>-0.0321982 -0.143407</point>
            <point>-0.126743 -0.168287</point>
            <point>-0.138907 -0.178459</point>
            <point>-0.147472 -0.191021</point>
            <point>-0.152612 -0.204726</point>
            <point>-0.152612 -0.220715</point>
            <point>-0.150746 -0.235978</point>
            <point>-0.144588 -0.249577</point>
            <point>-0.134325 -0.262149</point>
            <point>-0.121496 -0.27036</point>
            <point>-0.10764 -0.275235</point>
            <point>-0.0926418 -0.277035</point>
            <point>-0.0769904 -0.274213</point>
            <point>-0.0615955 -0.267799</point>
            <point>-0.000605438 -0.193129</point>
          </polyline>
          <polyline>
            <height>0.1</height>
            <point>-0.0401085 -0.133327</point>
            <point>-0.138961 -0.147488</point>
            <point>-0.155521 -0.164048</point>
            <point>-0.168654 -0.180037</point>
            <point>-0.176078 -0.200023</point>
            <point>-0.17722 -0.223436</point>
            <point>-0.173481 -0.243336</point>
            <point>-0.163529 -0.263623</point>
            <point>-0.149366 -0.279699</point>
            <point>-0.131759 -0.291565</point>
            <point>-0.113003 -0.299221</point>
            <point>-0.0908969 -0.301066</point>
            <point>-0.0690875 -0.29696</point>
            <point>-0.0493307 -0.287724</point>
            <point>0.0107182 -0.197705</point>
            <point>0.0601272 -0.111665</point>
            <point>0.105738 -0.0191367</point>
            <point>0.145777 0.0984226</point>
            <point>0.166222 0.187018</point>
            <point>0.17722 0.267953</point>
            <point>0.174158 0.277777</point>
            <point>0.16765 0.288112</point>
            <point>0.162436 0.293842</point>
            <point>0.154524 0.298314</point>
            <point>0.145409 0.301066</point>
            <point>0.134401 0.301066</point>
            <point>0.12477 0.298314</point>
            <point>0.116799 0.293669</point>
            <point>0.109919 0.286617</point>
            <point>0.105275 0.27819</point>
            <point>0.102867 0.267953</point>
            <point>0.105265 0.232247</point>
            <point>0.105265 0.196583</point>
            <point>0.102183 0.158496</point>
            <point>0.0964418 0.11907</point>
            <point>0.0864897 0.0788786</point>
            <point>0.0684993 0.0283524</point>
            <point>0.0401947 -0.0290691</point>
            <point>-0.000707322 -0.092784</point>
            <point>-0.0401085 -0.133327</point>
          </polyline>
        </geometry>
        <material>
          <lighting>1</lighting>
          <script>
            <uri>file://media/materials/scripts/gazebo.material</uri>
            <name>Gazebo/FlatBlack</name>
          </script>
          <shader type='pixel'>
            <normal_map>__default__</normal_map>
          </shader>
          <emissive>0 0 0 1</emissive>
          <ambient>0.1 0.1 0.1 1</ambient>
          <diffuse>0.1 0.1 0.1 1</diffuse>
          <specular>0.01 0.01 0.01 1</specular>
        </material>
        <transparency>0</transparency>
        <cast_shadows>1</cast_shadows>
      </visual>
      <collision name='collision'>
        <laser_retro>0</laser_retro>
        <max_contacts>10</max_contacts>
        <pose>-0.14 -0.28 -0.05 0 -0 0</pose>
        <geometry>
          <polyline>
            <height>0.1</height>
            <point>-0.000605438 -0.193129</point>
            <point>-0.0321982 -0.143407</point>
            <point>-0.126743 -0.168287</point>
            <point>-0.138907 -0.178459</point>
            <point>-0.147472 -0.191021</point>
            <point>-0.152612 -0.204726</point>
            <point>-0.152612 -0.220715</point>
            <point>-0.150746 -0.235978</point>
            <point>-0.144588 -0.249577</point>
            <point>-0.134325 -0.262149</point>
            <point>-0.121496 -0.27036</point>
            <point>-0.10764 -0.275235</point>
            <point>-0.0926418 -0.277035</point>
            <point>-0.0769904 -0.274213</point>
            <point>-0.0615955 -0.267799</point>
            <point>-0.000605438 -0.193129</point>
          </polyline>
          <polyline>
            <height>0.1</height>
            <point>-0.0401085 -0.133327</point>
            <point>-0.138961 -0.147488</point>
            <point>-0.155521 -0.164048</point>
            <point>-0.168654 -0.180037</point>
            <point>-0.176078 -0.200023</point>
            <point>-0.17722 -0.223436</point>
            <point>-0.173481 -0.243336</point>
            <point>-0.163529 -0.263623</point>
            <point>-0.149366 -0.279699</point>
            <point>-0.131759 -0.291565</point>
            <point>-0.113003 -0.299221</point>
            <point>-0.0908969 -0.301066</point>
            <point>-0.0690875 -0.29696</point>
            <point>-0.0493307 -0.287724</point>
            <point>0.0107182 -0.197705</point>
            <point>0.0601272 -0.111665</point>
            <point>0.105738 -0.0191367</point>
            <point>0.145777 0.0984226</point>
            <point>0.166222 0.187018</point>
            <point>0.17722 0.267953</point>
            <point>0.174158 0.277777</point>
            <point>0.16765 0.288112</point>
            <point>0.162436 0.293842</point>
            <point>0.154524 0.298314</point>
            <point>0.145409 0.301066</point>
            <point>0.134401 0.301066</point>
            <point>0.12477 0.298314</point>
            <point>0.116799 0.293669</point>
            <point>0.109919 0.286617</point>
            <point>0.105275 0.27819</point>
            <point>0.102867 0.267953</point>
            <point>0.105265 0.232247</point>
            <point>0.105265 0.196583</point>
            <point>0.102183 0.158496</point>
            <point>0.0964418 0.11907</point>
            <point>0.0864897 0.0788786</point>
            <point>0.0684993 0.0283524</point>
            <point>0.0401947 -0.0290691</point>
            <point>-0.000707322 -0.092784</point>
            <point>-0.0401085 -0.133327</point>
          </polyline>
        </geometry>
        <surface>
          <friction>
            <ode>
              <mu>1</mu>
              <mu2>1</mu2>
              <fdir1>0 0 0</fdir1>
              <slip1>0</slip1>
              <slip2>0</slip2>
            </ode>
            <torsional>
              <coefficient>1</coefficient>
              <patch_radius>0</patch_radius>
              <surface_radius>0</surface_radius>
              <use_patch_radius>1</use_patch_radius>
              <ode>
                <slip>0</slip>
              </ode>
            </torsional>
          </friction>
          <bounce>
            <restitution_coefficient>0</restitution_coefficient>
            <threshold>1e+06</threshold>
          </bounce>
          <contact>
            <collide_without_contact>0</collide_without_contact>
            <collide_without_contact_bitmask>1</collide_without_contact_bitmask>
            <collide_bitmask>1</collide_bitmask>
            <ode>
              <soft_cfm>0</soft_cfm>
              <soft_erp>0.2</soft_erp>
              <kp>1e+13</kp>
              <kd>1</kd>
              <max_vel>0.01</max_vel>
              <min_depth>0</min_depth>
            </ode>
            <bullet>
              <split_impulse>1</split_impulse>
              <split_impulse_penetration_threshold>-0.01</split_impulse_penetration_threshold>
              <soft_cfm>0</soft_cfm>
              <soft_erp>0.2</soft_erp>
              <kp>1e+13</kp>
              <kd>1</kd>
            </bullet>
          </contact>
        </surface>
      </collision>
    </link>
    <link name='upperleg_frontleft'>
      <inertial>
        <mass>1</mass>
        <inertia>
          <ixx>0.166667</ixx>
          <ixy>0</ixy>
          <ixz>0</ixz>
          <iyy>0.166667</iyy>
          <iyz>0</iyz>
          <izz>0.166667</izz>
        </inertia>
        <pose>0 0 0 0 -0 0</pose>
      </inertial>
      <pose>0.270233 -0.522543 0.849851 -1.56897 -1.5707 -1.57243</pose>
      <gravity>1</gravity>
      <self_collide>0</self_collide>
      <kinematic>0</kinematic>
      <enable_wind>0</enable_wind>
      <visual name='visual'>
        <pose>0 -0.25 -0.06 0 -0 0</pose>
        <geometry>
          <polyline>
            <height>0.12</height>
            <point>0.0128453 -0.315198</point>
            <point>0.0316557 -0.280522</point>
            <point>0.044765 -0.250686</point>
            <point>0.0548549 -0.222543</point>
            <point>0.0641881 -0.189091</point>
            <point>0.0709866 -0.153965</point>
            <point>0.0743858 -0.11714</point>
            <point>0.0743858 0.31597</point>
            <point>0.0678617 0.323607</point>
            <point>-0.0385426 0.323607</point>
            <point>-0.0461378 0.315113</point>
            <point>-0.0461378 -0.187787</point>
            <point>-0.073227 -0.255205</point>
            <point>-0.0743858 -0.269314</point>
            <point>-0.0720947 -0.28306</point>
            <point>-0.0657307 -0.296807</point>
            <point>-0.054731 -0.309351</point>
            <point>-0.044803 -0.316479</point>
            <point>-0.0300384 -0.32157</point>
            <point>-0.0155283 -0.323607</point>
            <point>-0.00166477 -0.321307</point>
            <point>0.0128453 -0.315198</point>
          </polyline>
        </geometry>
        <material>
          <lighting>1</lighting>
          <script>
            <uri>file://media/materials/scripts/gazebo.material</uri>
            <name>Gazebo/DarkYellow</name>
          </script>
          <shader type='pixel'>
            <normal_map>__default__</normal_map>
          </shader>
          <emissive>0 0 0 1</emissive>
          <ambient>0.7 0.7 0 1</ambient>
          <diffuse>0.7 0.7 0 1</diffuse>
        </material>
        <transparency>0</transparency>
        <cast_shadows>1</cast_shadows>
      </visual>
      <collision name='collision'>
        <laser_retro>0</laser_retro>
        <max_contacts>10</max_contacts>
        <pose>0 -0.25 -0.06 0 -0 0</pose>
        <geometry>
          <polyline>
            <height>0.12</height>
            <point>0.0128453 -0.315198</point>
            <point>0.0316557 -0.280522</point>
            <point>0.044765 -0.250686</point>
            <point>0.0548549 -0.222543</point>
            <point>0.0641881 -0.189091</point>
            <point>0.0709866 -0.153965</point>
            <point>0.0743858 -0.11714</point>
            <point>0.0743858 0.31597</point>
            <point>0.0678617 0.323607</point>
            <point>-0.0385426 0.323607</point>
            <point>-0.0461378 0.315113</point>
            <point>-0.0461378 -0.187787</point>
            <point>-0.073227 -0.255205</point>
            <point>-0.0743858 -0.269314</point>
            <point>-0.0720947 -0.28306</point>
            <point>-0.0657307 -0.296807</point>
            <point>-0.054731 -0.309351</point>
            <point>-0.044803 -0.316479</point>
            <point>-0.0300384 -0.32157</point>
            <point>-0.0155283 -0.323607</point>
            <point>-0.00166477 -0.321307</point>
            <point>0.0128453 -0.315198</point>
          </polyline>
        </geometry>
        <surface>
          <friction>
            <ode>
              <mu>1</mu>
              <mu2>1</mu2>
              <fdir1>0 0 0</fdir1>
              <slip1>0</slip1>
              <slip2>0</slip2>
            </ode>
            <torsional>
              <coefficient>1</coefficient>
              <patch_radius>0</patch_radius>
              <surface_radius>0</surface_radius>
              <use_patch_radius>1</use_patch_radius>
              <ode>
                <slip>0</slip>
              </ode>
            </torsional>
          </friction>
          <bounce>
            <restitution_coefficient>0</restitution_coefficient>
            <threshold>1e+06</threshold>
          </bounce>
          <contact>
            <collide_without_contact>0</collide_without_contact>
            <collide_without_contact_bitmask>1</collide_without_contact_bitmask>
            <collide_bitmask>1</collide_bitmask>
            <ode>
              <soft_cfm>0</soft_cfm>
              <soft_erp>0.2</soft_erp>
              <kp>1e+13</kp>
              <kd>1</kd>
              <max_vel>0.01</max_vel>
              <min_depth>0</min_depth>
            </ode>
            <bullet>
              <split_impulse>1</split_impulse>
              <split_impulse_penetration_threshold>-0.01</split_impulse_penetration_threshold>
              <soft_cfm>0</soft_cfm>
              <soft_erp>0.2</soft_erp>
              <kp>1e+13</kp>
              <kd>1</kd>
            </bullet>
          </contact>
        </surface>
      </collision>
    </link>
    <link name='upperleg_frontright'>
      <inertial>
        <mass>1</mass>
        <inertia>
          <ixx>0.166667</ixx>
          <ixy>0</ixy>
          <ixz>0</ixz>
          <iyy>0.166667</iyy>
          <iyz>0</iyz>
          <izz>0.166667</izz>
        </inertia>
        <pose>0 0 0 0 -0 0</pose>
      </inertial>
      <pose>-0.275 -0.53 0.85 1.57095 -1.5707 1.57044</pose>
      <gravity>1</gravity>
      <self_collide>0</self_collide>
      <kinematic>0</kinematic>
      <enable_wind>0</enable_wind>
      <visual name='visual'>
        <pose>0 -0.25 -0.06 0 -0 0</pose>
        <geometry>
          <polyline>
            <height>0.12</height>
            <point>0.0128453 -0.315198</point>
            <point>0.0316557 -0.280522</point>
            <point>0.044765 -0.250686</point>
            <point>0.0548549 -0.222543</point>
            <point>0.0641881 -0.189091</point>
            <point>0.0709866 -0.153965</point>
            <point>0.0743858 -0.11714</point>
            <point>0.0743858 0.31597</point>
            <point>0.0678617 0.323607</point>
            <point>-0.0385426 0.323607</point>
            <point>-0.0461378 0.315113</point>
            <point>-0.0461378 -0.187787</point>
            <point>-0.073227 -0.255205</point>
            <point>-0.0743858 -0.269314</point>
            <point>-0.0720947 -0.28306</point>
            <point>-0.0657307 -0.296807</point>
            <point>-0.054731 -0.309351</point>
            <point>-0.044803 -0.316479</point>
            <point>-0.0300384 -0.32157</point>
            <point>-0.0155283 -0.323607</point>
            <point>-0.00166477 -0.321307</point>
            <point>0.0128453 -0.315198</point>
          </polyline>
        </geometry>
        <material>
          <lighting>1</lighting>
          <script>
            <uri>file://media/materials/scripts/gazebo.material</uri>
            <name>Gazebo/DarkYellow</name>
          </script>
          <shader type='pixel'>
            <normal_map>__default__</normal_map>
          </shader>
          <emissive>0 0 0 1</emissive>
          <ambient>0.7 0.7 0 1</ambient>
          <diffuse>0.7 0.7 0 1</diffuse>
        </material>
        <transparency>0</transparency>
        <cast_shadows>1</cast_shadows>
      </visual>
      <collision name='collision'>
        <laser_retro>0</laser_retro>
        <max_contacts>10</max_contacts>
        <pose>0 -0.25 -0.06 0 -0 0</pose>
        <geometry>
          <polyline>
            <height>0.12</height>
            <point>0.0128453 -0.315198</point>
            <point>0.0316557 -0.280522</point>
            <point>0.044765 -0.250686</point>
            <point>0.0548549 -0.222543</point>
            <point>0.0641881 -0.189091</point>
            <point>0.0709866 -0.153965</point>
            <point>0.0743858 -0.11714</point>
            <point>0.0743858 0.31597</point>
            <point>0.0678617 0.323607</point>
            <point>-0.0385426 0.323607</point>
            <point>-0.0461378 0.315113</point>
            <point>-0.0461378 -0.187787</point>
            <point>-0.073227 -0.255205</point>
            <point>-0.0743858 -0.269314</point>
            <point>-0.0720947 -0.28306</point>
            <point>-0.0657307 -0.296807</point>
            <point>-0.054731 -0.309351</point>
            <point>-0.044803 -0.316479</point>
            <point>-0.0300384 -0.32157</point>
            <point>-0.0155283 -0.323607</point>
            <point>-0.00166477 -0.321307</point>
            <point>0.0128453 -0.315198</point>
          </polyline>
        </geometry>
        <surface>
          <friction>
            <ode>
              <mu>1</mu>
              <mu2>1</mu2>
              <fdir1>0 0 0</fdir1>
              <slip1>0</slip1>
              <slip2>0</slip2>
            </ode>
            <torsional>
              <coefficient>1</coefficient>
              <patch_radius>0</patch_radius>
              <surface_radius>0</surface_radius>
              <use_patch_radius>1</use_patch_radius>
              <ode>
                <slip>0</slip>
              </ode>
            </torsional>
          </friction>
          <bounce>
            <restitution_coefficient>0</restitution_coefficient>
            <threshold>1e+06</threshold>
          </bounce>
          <contact>
            <collide_without_contact>0</collide_without_contact>
            <collide_without_contact_bitmask>1</collide_without_contact_bitmask>
            <collide_bitmask>1</collide_bitmask>
            <ode>
              <soft_cfm>0</soft_cfm>
              <soft_erp>0.2</soft_erp>
              <kp>1e+13</kp>
              <kd>1</kd>
              <max_vel>0.01</max_vel>
              <min_depth>0</min_depth>
            </ode>
            <bullet>
              <split_impulse>1</split_impulse>
              <split_impulse_penetration_threshold>-0.01</split_impulse_penetration_threshold>
              <soft_cfm>0</soft_cfm>
              <soft_erp>0.2</soft_erp>
              <kp>1e+13</kp>
              <kd>1</kd>
            </bullet>
          </contact>
        </surface>
      </collision>
    </link>
    <link name='upperleg_rearleft'>
      <inertial>
        <mass>1</mass>
        <inertia>
          <ixx>0.166667</ixx>
          <ixy>0</ixy>
          <ixz>0</ixz>
          <iyy>0.166667</iyy>
          <iyz>0</iyz>
          <izz>0.166667</izz>
        </inertia>
        <pose>0 0 0 0 -0 0</pose>
      </inertial>
      <pose>0.275015 0.575 0.85 1.57095 -1.5707 1.57044</pose>
      <gravity>1</gravity>
      <self_collide>0</self_collide>
      <kinematic>0</kinematic>
      <enable_wind>0</enable_wind>
      <visual name='visual'>
        <pose>0 -0.25 -0.06 0 -0 0</pose>
        <geometry>
          <polyline>
            <height>0.12</height>
            <point>0.0128453 -0.315198</point>
            <point>0.0316557 -0.280522</point>
            <point>0.044765 -0.250686</point>
            <point>0.0548549 -0.222543</point>
            <point>0.0641881 -0.189091</point>
            <point>0.0709866 -0.153965</point>
            <point>0.0743858 -0.11714</point>
            <point>0.0743858 0.31597</point>
            <point>0.0678617 0.323607</point>
            <point>-0.0385426 0.323607</point>
            <point>-0.0461378 0.315113</point>
            <point>-0.0461378 -0.187787</point>
            <point>-0.073227 -0.255205</point>
            <point>-0.0743858 -0.269314</point>
            <point>-0.0720947 -0.28306</point>
            <point>-0.0657307 -0.296807</point>
            <point>-0.054731 -0.309351</point>
            <point>-0.044803 -0.316479</point>
            <point>-0.0300384 -0.32157</point>
            <point>-0.0155283 -0.323607</point>
            <point>-0.00166477 -0.321307</point>
            <point>0.0128453 -0.315198</point>
          </polyline>
        </geometry>
        <material>
          <lighting>1</lighting>
          <script>
            <uri>file://media/materials/scripts/gazebo.material</uri>
            <name>Gazebo/DarkYellow</name>
          </script>
          <shader type='pixel'>
            <normal_map>__default__</normal_map>
          </shader>
          <emissive>0 0 0 1</emissive>
          <ambient>0.7 0.7 0 1</ambient>
          <diffuse>0.7 0.7 0 1</diffuse>
        </material>
        <transparency>0</transparency>
        <cast_shadows>1</cast_shadows>
      </visual>
      <collision name='collision'>
        <laser_retro>0</laser_retro>
        <max_contacts>10</max_contacts>
        <pose>0 -0.25 -0.06 0 -0 0</pose>
        <geometry>
          <polyline>
            <height>0.12</height>
            <point>0.0128453 -0.315198</point>
            <point>0.0316557 -0.280522</point>
            <point>0.044765 -0.250686</point>
            <point>0.0548549 -0.222543</point>
            <point>0.0641881 -0.189091</point>
            <point>0.0709866 -0.153965</point>
            <point>0.0743858 -0.11714</point>
            <point>0.0743858 0.31597</point>
            <point>0.0678617 0.323607</point>
            <point>-0.0385426 0.323607</point>
            <point>-0.0461378 0.315113</point>
            <point>-0.0461378 -0.187787</point>
            <point>-0.073227 -0.255205</point>
            <point>-0.0743858 -0.269314</point>
            <point>-0.0720947 -0.28306</point>
            <point>-0.0657307 -0.296807</point>
            <point>-0.054731 -0.309351</point>
            <point>-0.044803 -0.316479</point>
            <point>-0.0300384 -0.32157</point>
            <point>-0.0155283 -0.323607</point>
            <point>-0.00166477 -0.321307</point>
            <point>0.0128453 -0.315198</point>
          </polyline>
        </geometry>
        <surface>
          <friction>
            <ode>
              <mu>1</mu>
              <mu2>1</mu2>
              <fdir1>0 0 0</fdir1>
              <slip1>0</slip1>
              <slip2>0</slip2>
            </ode>
            <torsional>
              <coefficient>1</coefficient>
              <patch_radius>0</patch_radius>
              <surface_radius>0</surface_radius>
              <use_patch_radius>1</use_patch_radius>
              <ode>
                <slip>0</slip>
              </ode>
            </torsional>
          </friction>
          <bounce>
            <restitution_coefficient>0</restitution_coefficient>
            <threshold>1e+06</threshold>
          </bounce>
          <contact>
            <collide_without_contact>0</collide_without_contact>
            <collide_without_contact_bitmask>1</collide_without_contact_bitmask>
            <collide_bitmask>1</collide_bitmask>
            <ode>
              <soft_cfm>0</soft_cfm>
              <soft_erp>0.2</soft_erp>
              <kp>1e+13</kp>
              <kd>1</kd>
              <max_vel>0.01</max_vel>
              <min_depth>0</min_depth>
            </ode>
            <bullet>
              <split_impulse>1</split_impulse>
              <split_impulse_penetration_threshold>-0.01</split_impulse_penetration_threshold>
              <soft_cfm>0</soft_cfm>
              <soft_erp>0.2</soft_erp>
              <kp>1e+13</kp>
              <kd>1</kd>
            </bullet>
          </contact>
        </surface>
      </collision>
    </link>
    <link name='upperleg_rearright'>
      <inertial>
        <mass>1</mass>
        <inertia>
          <ixx>0.166667</ixx>
          <ixy>0</ixy>
          <ixz>0</ixz>
          <iyy>0.166667</iyy>
          <iyz>0</iyz>
          <izz>0.166667</izz>
        </inertia>
        <pose>0 0 0 0 -0 0</pose>
      </inertial>
      <pose>-0.314494 0.575 0.85 1.57095 -1.5707 1.57044</pose>
      <gravity>1</gravity>
      <self_collide>0</self_collide>
      <kinematic>0</kinematic>
      <enable_wind>0</enable_wind>
      <visual name='visual'>
        <pose>0 -0.25 -0.06 0 -0 0</pose>
        <geometry>
          <polyline>
            <height>0.12</height>
            <point>0.0128453 -0.315198</point>
            <point>0.0316557 -0.280522</point>
            <point>0.044765 -0.250686</point>
            <point>0.0548549 -0.222543</point>
            <point>0.0641881 -0.189091</point>
            <point>0.0709866 -0.153965</point>
            <point>0.0743858 -0.11714</point>
            <point>0.0743858 0.31597</point>
            <point>0.0678617 0.323607</point>
            <point>-0.0385426 0.323607</point>
            <point>-0.0461378 0.315113</point>
            <point>-0.0461378 -0.187787</point>
            <point>-0.073227 -0.255205</point>
            <point>-0.0743858 -0.269314</point>
            <point>-0.0720947 -0.28306</point>
            <point>-0.0657307 -0.296807</point>
            <point>-0.054731 -0.309351</point>
            <point>-0.044803 -0.316479</point>
            <point>-0.0300384 -0.32157</point>
            <point>-0.0155283 -0.323607</point>
            <point>-0.00166477 -0.321307</point>
            <point>0.0128453 -0.315198</point>
          </polyline>
        </geometry>
        <material>
          <lighting>1</lighting>
          <script>
            <uri>file://media/materials/scripts/gazebo.material</uri>
            <name>Gazebo/DarkYellow</name>
          </script>
          <shader type='pixel'>
            <normal_map>__default__</normal_map>
          </shader>
          <emissive>0 0 0 1</emissive>
          <ambient>0.7 0.7 0 1</ambient>
          <diffuse>0.7 0.7 0 1</diffuse>
        </material>
        <transparency>0</transparency>
        <cast_shadows>1</cast_shadows>
      </visual>
      <collision name='collision'>
        <laser_retro>0</laser_retro>
        <max_contacts>10</max_contacts>
        <pose>0 -0.25 -0.06 0 -0 0</pose>
        <geometry>
          <polyline>
            <height>0.12</height>
            <point>0.0128453 -0.315198</point>
            <point>0.0316557 -0.280522</point>
            <point>0.044765 -0.250686</point>
            <point>0.0548549 -0.222543</point>
            <point>0.0641881 -0.189091</point>
            <point>0.0709866 -0.153965</point>
            <point>0.0743858 -0.11714</point>
            <point>0.0743858 0.31597</point>
            <point>0.0678617 0.323607</point>
            <point>-0.0385426 0.323607</point>
            <point>-0.0461378 0.315113</point>
            <point>-0.0461378 -0.187787</point>
            <point>-0.073227 -0.255205</point>
            <point>-0.0743858 -0.269314</point>
            <point>-0.0720947 -0.28306</point>
            <point>-0.0657307 -0.296807</point>
            <point>-0.054731 -0.309351</point>
            <point>-0.044803 -0.316479</point>
            <point>-0.0300384 -0.32157</point>
            <point>-0.0155283 -0.323607</point>
            <point>-0.00166477 -0.321307</point>
            <point>0.0128453 -0.315198</point>
          </polyline>
        </geometry>
        <surface>
          <friction>
            <ode>
              <mu>1</mu>
              <mu2>1</mu2>
              <fdir1>0 0 0</fdir1>
              <slip1>0</slip1>
              <slip2>0</slip2>
            </ode>
            <torsional>
              <coefficient>1</coefficient>
              <patch_radius>0</patch_radius>
              <surface_radius>0</surface_radius>
              <use_patch_radius>1</use_patch_radius>
              <ode>
                <slip>0</slip>
              </ode>
            </torsional>
          </friction>
          <bounce>
            <restitution_coefficient>0</restitution_coefficient>
            <threshold>1e+06</threshold>
          </bounce>
          <contact>
            <collide_without_contact>0</collide_without_contact>
            <collide_without_contact_bitmask>1</collide_without_contact_bitmask>
            <collide_bitmask>1</collide_bitmask>
            <ode>
              <soft_cfm>0</soft_cfm>
              <soft_erp>0.2</soft_erp>
              <kp>1e+13</kp>
              <kd>1</kd>
              <max_vel>0.01</max_vel>
              <min_depth>0</min_depth>
            </ode>
            <bullet>
              <split_impulse>1</split_impulse>
              <split_impulse_penetration_threshold>-0.01</split_impulse_penetration_threshold>
              <soft_cfm>0</soft_cfm>
              <soft_erp>0.2</soft_erp>
              <kp>1e+13</kp>
              <kd>1</kd>
            </bullet>
          </contact>
        </surface>
      </collision>
    </link>
    <joint name='frontleft_knee' type='revolute'>
      <parent>upperleg_frontleft</parent>
      <child>bottomleg_frontleft</child>
      <pose>0 0 0 0 -0 0</pose>
      <axis>
        <xyz>0 0 1</xyz>
        <limit>
          <lower>-1.79769e+308</lower>
          <upper>1.79769e+308</upper>
          <effort>-1</effort>
          <velocity>-1</velocity>
        </limit>
        <dynamics>
          <spring_reference>0</spring_reference>
          <spring_stiffness>0</spring_stiffness>
          <damping>0</damping>
          <friction>0</friction>
        </dynamics>
      </axis>
      <physics>
        <ode>
          <limit>
            <cfm>0</cfm>
            <erp>0.2</erp>
          </limit>
          <suspension>
            <cfm>0</cfm>
            <erp>0.2</erp>
          </suspension>
        </ode>
      </physics>
    </joint>
    <joint name='frontleft_shoulder' type='revolute2'>
      <parent>body</parent>
      <child>upperleg_frontleft</child>
      <pose>0 0 0 0 -0 0</pose>
      <axis>
        <xyz>0 0 1</xyz>
        <limit>
          <lower>-1.79769e+308</lower>
          <upper>1.79769e+308</upper>
          <effort>-1</effort>
          <velocity>-1</velocity>
        </limit>
        <dynamics>
          <spring_reference>0</spring_reference>
          <spring_stiffness>0</spring_stiffness>
          <damping>0</damping>
          <friction>0</friction>
        </dynamics>
      </axis>
      <axis2>
        <xyz>1 0 0</xyz>
        <limit>
          <lower>-1.79769e+308</lower>
          <upper>1.79769e+308</upper>
          <effort>-1</effort>
          <velocity>-1</velocity>
        </limit>
        <dynamics>
          <spring_reference>0</spring_reference>
          <spring_stiffness>0</spring_stiffness>
          <damping>0</damping>
          <friction>0</friction>
        </dynamics>
      </axis2>
      <physics>
        <ode>
          <limit>
            <cfm>0</cfm>
            <erp>0.2</erp>
          </limit>
          <suspension>
            <cfm>0</cfm>
            <erp>0.2</erp>
          </suspension>
        </ode>
      </physics>
    </joint>
    <joint name='frontright_knee' type='revolute'>
      <parent>upperleg_frontright</parent>
      <child>bottomleg_frontright</child>
      <pose>0 0 0 0 -0 0</pose>
      <axis>
        <xyz>0 0 1</xyz>
        <limit>
          <lower>-1.79769e+308</lower>
          <upper>1.79769e+308</upper>
          <effort>-1</effort>
          <velocity>-1</velocity>
        </limit>
        <dynamics>
          <spring_reference>0</spring_reference>
          <spring_stiffness>0</spring_stiffness>
          <damping>0</damping>
          <friction>0</friction>
        </dynamics>
      </axis>
      <physics>
        <ode>
          <limit>
            <cfm>0</cfm>
            <erp>0.2</erp>
          </limit>
          <suspension>
            <cfm>0</cfm>
            <erp>0.2</erp>
          </suspension>
        </ode>
      </physics>
    </joint>
    <joint name='frontright_shoulder' type='revolute2'>
      <parent>body</parent>
      <child>upperleg_frontright</child>
      <pose>0 0 0 0 -0 0</pose>
      <axis>
        <xyz>0 0 1</xyz>
        <limit>
          <lower>-1.79769e+308</lower>
          <upper>1.79769e+308</upper>
          <effort>-1</effort>
          <velocity>-1</velocity>
        </limit>
        <dynamics>
          <spring_reference>0</spring_reference>
          <spring_stiffness>0</spring_stiffness>
          <damping>0</damping>
          <friction>0</friction>
        </dynamics>
      </axis>
      <axis2>
        <xyz>1 0 0</xyz>
        <limit>
          <lower>-1.79769e+308</lower>
          <upper>1.79769e+308</upper>
          <effort>-1</effort>
          <velocity>-1</velocity>
        </limit>
        <dynamics>
          <spring_reference>0</spring_reference>
          <spring_stiffness>0</spring_stiffness>
          <damping>0</damping>
          <friction>0</friction>
        </dynamics>
      </axis2>
      <physics>
        <ode>
          <limit>
            <cfm>0</cfm>
            <erp>0.2</erp>
          </limit>
          <suspension>
            <cfm>0</cfm>
            <erp>0.2</erp>
          </suspension>
        </ode>
      </physics>
    </joint>
    <joint name='rearleft_knee' type='revolute'>
      <parent>upperleg_rearleft</parent>
      <child>bottomleg_rearleft</child>
      <pose>0 0 0 0 -0 0</pose>
      <axis>
        <xyz>0 0 1</xyz>
        <limit>
          <lower>-1.79769e+308</lower>
          <upper>1.79769e+308</upper>
          <effort>-1</effort>
          <velocity>-1</velocity>
        </limit>
        <dynamics>
          <spring_reference>0</spring_reference>
          <spring_stiffness>0</spring_stiffness>
          <damping>0</damping>
          <friction>0</friction>
        </dynamics>
      </axis>
      <physics>
        <ode>
          <limit>
            <cfm>0</cfm>
            <erp>0.2</erp>
          </limit>
          <suspension>
            <cfm>0</cfm>
            <erp>0.2</erp>
          </suspension>
        </ode>
      </physics>
    </joint>
    <joint name='rearleft_shoulder' type='revolute2'>
      <parent>body</parent>
      <child>upperleg_rearleft</child>
      <pose>0 0 0 0 -0 0</pose>
      <axis>
        <xyz>0 0 1</xyz>
        <limit>
          <lower>-1.79769e+308</lower>
          <upper>1.79769e+308</upper>
          <effort>-1</effort>
          <velocity>-1</velocity>
        </limit>
        <dynamics>
          <spring_reference>0</spring_reference>
          <spring_stiffness>0</spring_stiffness>
          <damping>0</damping>
          <friction>0</friction>
        </dynamics>
      </axis>
      <axis2>
        <xyz>1 0 0</xyz>
        <limit>
          <lower>-1.79769e+308</lower>
          <upper>1.79769e+308</upper>
          <effort>-1</effort>
          <velocity>-1</velocity>
        </limit>
        <dynamics>
          <spring_reference>0</spring_reference>
          <spring_stiffness>0</spring_stiffness>
          <damping>0</damping>
          <friction>0</friction>
        </dynamics>
      </axis2>
      <physics>
        <ode>
          <limit>
            <cfm>0</cfm>
            <erp>0.2</erp>
          </limit>
          <suspension>
            <cfm>0</cfm>
            <erp>0.2</erp>
          </suspension>
        </ode>
      </physics>
    </joint>
    <joint name='rearright_knee' type='revolute'>
      <parent>upperleg_rearright</parent>
      <child>bottomleg_rearright</child>
      <pose>0 0 0 0 -0 0</pose>
      <axis>
        <xyz>0 0 1</xyz>
        <limit>
          <lower>-1.79769e+308</lower>
          <upper>1.79769e+308</upper>
          <effort>-1</effort>
          <velocity>-1</velocity>
        </limit>
        <dynamics>
          <spring_reference>0</spring_reference>
          <spring_stiffness>0</spring_stiffness>
          <damping>0</damping>
          <friction>0</friction>
        </dynamics>
      </axis>
      <physics>
        <ode>
          <limit>
            <cfm>0</cfm>
            <erp>0.2</erp>
          </limit>
          <suspension>
            <cfm>0</cfm>
            <erp>0.2</erp>
          </suspension>
        </ode>
      </physics>
    </joint>
    <joint name='rearright_shoulder' type='revolute2'>
      <parent>body</parent>
      <child>upperleg_rearright</child>
      <pose>0 0 0 0 -0 0</pose>
      <axis>
        <xyz>0 0 1</xyz>
        <limit>
          <lower>-1.79769e+308</lower>
          <upper>1.79769e+308</upper>
          <effort>-1</effort>
          <velocity>-1</velocity>
        </limit>
        <dynamics>
          <spring_reference>0</spring_reference>
          <spring_stiffness>0</spring_stiffness>
          <damping>0</damping>
          <friction>0</friction>
        </dynamics>
      </axis>
      <axis2>
        <xyz>1 0 0</xyz>
        <limit>
          <lower>-1.79769e+308</lower>
          <upper>1.79769e+308</upper>
          <effort>-1</effort>
          <velocity>-1</velocity>
        </limit>
        <dynamics>
          <spring_reference>0</spring_reference>
          <spring_stiffness>0</spring_stiffness>
          <damping>0</damping>
          <friction>0</friction>
        </dynamics>
      </axis2>
      <physics>
        <ode>
          <limit>
            <cfm>0</cfm>
            <erp>0.2</erp>
          </limit>
          <suspension>
            <cfm>0</cfm>
            <erp>0.2</erp>
          </suspension>
        </ode>
      </physics>
    </joint>
    <static>0</static>
    <allow_auto_disable>1</allow_auto_disable>
  </model>
</sdf>
